label(): error while preparing labels: 
**********************************************************************
  Resource [93mpunkt[0m not found.
  Please use the NLTK Downloader to obtain the resource:

  [31m>>> import nltk
  >>> nltk.download('punkt')
  [0m
  For more information see: https://www.nltk.org/data.html

  Attempted to load [93mtokenizers/punkt/PY3/english.pickle[0m

  Searched in:
    - '/root/nltk_data'
    - '/usr/local/nltk_data'
    - '/usr/local/share/nltk_data'
    - '/usr/local/lib/nltk_data'
    - '/usr/share/nltk_data'
    - '/usr/local/share/nltk_data'
    - '/usr/lib/nltk_data'
    - '/usr/local/lib/nltk_data'
    - ''
**********************************************************************

Traceback (most recent call last):
  File "/app/labellertool/routes.py", line 103, in label
    sentences, pos = obj.labelit()
  File "/app/labellertool/generate_data.py", line 56, in labelit
    val_new, val_pos = self.sent_tag(resume)
  File "/app/labellertool/generate_data.py", line 28, in sent_tag
    texts = prepare_text(resume,True)
  File "/app/labellertool/datareader.py", line 142, in prepare_text
    file_content = reader_choice[ext](file, dolower=dolower)
  File "/app/labellertool/datareader.py", line 76, in pdf_to_text
    sentences = sent_tokenize(text)
  File "/usr/local/lib/python3.6/site-packages/nltk/tokenize/__init__.py", line 106, in sent_tokenize
    tokenizer = load("tokenizers/punkt/{0}.pickle".format(language))
  File "/usr/local/lib/python3.6/site-packages/nltk/data.py", line 752, in load
    opened_resource = _open(resource_url)
  File "/usr/local/lib/python3.6/site-packages/nltk/data.py", line 877, in _open
    return find(path_, path + [""]).open()
  File "/usr/local/lib/python3.6/site-packages/nltk/data.py", line 585, in find
    raise LookupError(resource_not_found)
LookupError: 
**********************************************************************
  Resource [93mpunkt[0m not found.
  Please use the NLTK Downloader to obtain the resource:

  [31m>>> import nltk
  >>> nltk.download('punkt')
  [0m
  For more information see: https://www.nltk.org/data.html

  Attempted to load [93mtokenizers/punkt/PY3/english.pickle[0m

  Searched in:
    - '/root/nltk_data'
    - '/usr/local/nltk_data'
    - '/usr/local/share/nltk_data'
    - '/usr/local/lib/nltk_data'
    - '/usr/share/nltk_data'
    - '/usr/local/share/nltk_data'
    - '/usr/lib/nltk_data'
    - '/usr/local/lib/nltk_data'
    - ''
**********************************************************************


label(): error while preparing labels: 
**********************************************************************
  Resource [93mpunkt[0m not found.
  Please use the NLTK Downloader to obtain the resource:

  [31m>>> import nltk
  >>> nltk.download('punkt')
  [0m
  For more information see: https://www.nltk.org/data.html

  Attempted to load [93mtokenizers/punkt/PY3/english.pickle[0m

  Searched in:
    - '/root/nltk_data'
    - '/usr/local/nltk_data'
    - '/usr/local/share/nltk_data'
    - '/usr/local/lib/nltk_data'
    - '/usr/share/nltk_data'
    - '/usr/local/share/nltk_data'
    - '/usr/lib/nltk_data'
    - '/usr/local/lib/nltk_data'
    - ''
**********************************************************************

Traceback (most recent call last):
  File "/app/labellertool/routes.py", line 103, in label
    sentences, pos = obj.labelit()
  File "/app/labellertool/generate_data.py", line 56, in labelit
    val_new, val_pos = self.sent_tag(resume)
  File "/app/labellertool/generate_data.py", line 28, in sent_tag
    texts = prepare_text(resume,True)
  File "/app/labellertool/datareader.py", line 142, in prepare_text
    file_content = reader_choice[ext](file, dolower=dolower)
  File "/app/labellertool/datareader.py", line 76, in pdf_to_text
    sentences = sent_tokenize(text)
  File "/usr/local/lib/python3.6/site-packages/nltk/tokenize/__init__.py", line 106, in sent_tokenize
    tokenizer = load("tokenizers/punkt/{0}.pickle".format(language))
  File "/usr/local/lib/python3.6/site-packages/nltk/data.py", line 752, in load
    opened_resource = _open(resource_url)
  File "/usr/local/lib/python3.6/site-packages/nltk/data.py", line 877, in _open
    return find(path_, path + [""]).open()
  File "/usr/local/lib/python3.6/site-packages/nltk/data.py", line 585, in find
    raise LookupError(resource_not_found)
LookupError: 
**********************************************************************
  Resource [93mpunkt[0m not found.
  Please use the NLTK Downloader to obtain the resource:

  [31m>>> import nltk
  >>> nltk.download('punkt')
  [0m
  For more information see: https://www.nltk.org/data.html

  Attempted to load [93mtokenizers/punkt/PY3/english.pickle[0m

  Searched in:
    - '/root/nltk_data'
    - '/usr/local/nltk_data'
    - '/usr/local/share/nltk_data'
    - '/usr/local/lib/nltk_data'
    - '/usr/share/nltk_data'
    - '/usr/local/share/nltk_data'
    - '/usr/lib/nltk_data'
    - '/usr/local/lib/nltk_data'
    - ''
**********************************************************************


label(): error while preparing labels: 
**********************************************************************
  Resource [93mpunkt[0m not found.
  Please use the NLTK Downloader to obtain the resource:

  [31m>>> import nltk
  >>> nltk.download('punkt')
  [0m
  For more information see: https://www.nltk.org/data.html

  Attempted to load [93mtokenizers/punkt/PY3/english.pickle[0m

  Searched in:
    - '/root/nltk_data'
    - '/usr/local/nltk_data'
    - '/usr/local/share/nltk_data'
    - '/usr/local/lib/nltk_data'
    - '/usr/share/nltk_data'
    - '/usr/local/share/nltk_data'
    - '/usr/lib/nltk_data'
    - '/usr/local/lib/nltk_data'
    - ''
**********************************************************************

Traceback (most recent call last):
  File "/app/labellertool/routes.py", line 103, in label
    sentences, pos = obj.labelit()
  File "/app/labellertool/generate_data.py", line 56, in labelit
    val_new, val_pos = self.sent_tag(resume)
  File "/app/labellertool/generate_data.py", line 28, in sent_tag
    texts = prepare_text(resume,True)
  File "/app/labellertool/datareader.py", line 142, in prepare_text
    file_content = reader_choice[ext](file, dolower=dolower)
  File "/app/labellertool/datareader.py", line 76, in pdf_to_text
    sentences = sent_tokenize(text)
  File "/usr/local/lib/python3.6/site-packages/nltk/tokenize/__init__.py", line 106, in sent_tokenize
    tokenizer = load("tokenizers/punkt/{0}.pickle".format(language))
  File "/usr/local/lib/python3.6/site-packages/nltk/data.py", line 752, in load
    opened_resource = _open(resource_url)
  File "/usr/local/lib/python3.6/site-packages/nltk/data.py", line 877, in _open
    return find(path_, path + [""]).open()
  File "/usr/local/lib/python3.6/site-packages/nltk/data.py", line 585, in find
    raise LookupError(resource_not_found)
LookupError: 
**********************************************************************
  Resource [93mpunkt[0m not found.
  Please use the NLTK Downloader to obtain the resource:

  [31m>>> import nltk
  >>> nltk.download('punkt')
  [0m
  For more information see: https://www.nltk.org/data.html

  Attempted to load [93mtokenizers/punkt/PY3/english.pickle[0m

  Searched in:
    - '/root/nltk_data'
    - '/usr/local/nltk_data'
    - '/usr/local/share/nltk_data'
    - '/usr/local/lib/nltk_data'
    - '/usr/share/nltk_data'
    - '/usr/local/share/nltk_data'
    - '/usr/lib/nltk_data'
    - '/usr/local/lib/nltk_data'
    - ''
**********************************************************************


